<?xml version="1.0" ?>
<robot name="rotation_stage" xmlns:xacro="http://www.ros.org/wiki/xacro">

<xacro:include filename="$(find micro_resector_description)/urdf/stage/stage.trans" />
<xacro:include filename="$(find micro_resector_description)/urdf/stage/stage.gazebo" />

<xacro:macro name="rotation_stage" params="prefix hardware_interface">
  <link name="${prefix}_rot_base_link">
    <inertial>
      <origin rpy="0 0 0" xyz="0.0 0.0075 0.0"/>
      <mass value="0.058579061972031825"/>
      <inertia ixx="1.2e-05" ixy="-0.0" ixz="-0.0" iyy="2.4e-05" iyz="0.0" izz="1.2e-05"/>
    </inertial>
    <visual>
      <origin rpy="0 0 0" xyz="0 0.01 0"/>
      <geometry>
        <mesh filename="package://micro_resector_description/meshes/stage/rot_base_link.stl" scale="0.001 0.001 0.001"/>
      </geometry>
      <material name="silver"/>
    </visual>
    <collision>
      <origin rpy="0 0 0" xyz="0 0.01 0"/>
      <geometry>
        <mesh filename="package://micro_resector_description/meshes/stage/rot_base_link.stl" scale="0.001 0.001 0.001"/>
      </geometry>
    </collision>
  </link>

  <link name="${prefix}_rot_stage_link">
    <inertial>
      <origin rpy="0 0 0" xyz="0.0 -0.00028 0.0"/>
      <mass value="0.11339718225370693"/>
      <inertia ixx="2.3e-05" ixy="0.0" ixz="0.0" iyy="4.6e-05" iyz="0.0" izz="2.3e-05"/>
    </inertial>
    <visual>
      <origin rpy="0 0 0" xyz="0.0 -0.005 -0.0"/>
      <geometry>
        <mesh filename="package://micro_resector_description/meshes/stage/rot_stage_link.stl" scale="0.001 0.001 0.001"/>
      </geometry>
      <material name="silver"/>
    </visual>
    <collision>
      <origin rpy="0 0 0" xyz="0.0 -0.005 -0.0"/>
      <geometry>
        <mesh filename="package://micro_resector_description/meshes/stage/rot_stage_link.stl" scale="0.001 0.001 0.001"/>
      </geometry>
    </collision>
  </link>

  <joint name="${prefix}_rot_joint" type="continuous">
    <origin rpy="0 ${pi/4} 0" xyz="0.0 0.015 0.0"/>
    <parent link="${prefix}_rot_base_link"/>
    <child link="${prefix}_rot_stage_link"/>
    <axis xyz="0 -1 0.0"/>
    <limit effort="100" velocity="${(pi/180) * 15}"/>
  </joint>

  <xacro:stage_gazebo prefix="${prefix}" type="rot"/>
  <xacro:stage_transmission prefix="${prefix}" hardware_interface="${hardware_interface}" type="rot"/>

</xacro:macro>

</robot>
